Workbook
Name Slicer_Diabetes_Status: #REF!
Name ExternalData_1: 'Customer Names'!$E$1:$H$2336
Name ExternalData_1: 'Medical Examinations'!$J$1:$S$2336
Name ExternalData_3: 'Hospitalisation Details'!$K$1:$R$2338
Name Slicer_Weight_Status: #REF!

Sheet Customer Names
A1: Customer ID | B1: name | E1: Customer ID | F1: Title | G1: First Name | H1: Last Name
A2: Id1 | B2: Hawks, Ms. Kelly | E2: Id1 | F2: Ms | G2: Kelly | H2: Hawks
A3: Id2 | B3: Lehner, Mr. Matthew D | E3: Id2 | F3: Mr | G3: Matthew D | H3: Lehner
A4: Id3 | B4: Lu, Mr. Phil | E4: Id3 | F4: Mr | G4: Phil | H4: Lu
A5: Id4 | B5: Osborne, Ms. Kelsey | E5: Id4 | F5: Ms | G5: Kelsey | H5: Osborne
A6: Id5 | B6: Kadala, Ms. Kristyn | E6: Id5 | F6: Ms | G6: Kristyn | H6: Kadala
A7: Id6 | B7: Baker, Mr. Russell B. | E7: Id6 | F7: Mr | G7: Russell B | H7: Baker
A8: Id7 | B8: Macpherson, Mr. Scott | E8: Id7 | F8: Mr | G8: Scott | H8: Macpherson
A9: Id8 | B9: Hallman, Mr. Stephen | E9: Id8 | F9: Mr | G9: Stephen | H9: Hallman
A10: Id9 | B10: Moran, Mr. Patrick R. | E10: Id9 | F10: Mr | G10: Patrick R | H10: Moran
A11: Id10 | B11: Benner, Ms. Brooke N. | E11: Id10 | F11: Ms | G11: Brooke N | H11: Benner
A12: Id11 | B12: Fierro Vargas, Ms. Paola Andrea | E12: Id11 | F12: Ms | G12: Paola Andrea | H12: Fierro Vargas
... A2336: Id2335 | B2336: German, Mr. Aaron K | E2336: Id2335 | F2336: Mr | G2336: Aaron K | H2336: German

Sheet Medical Examinations
A1: Customer ID | B1: BMI | C1: HBA1C | D1: Heart Issues | E1: Any Transplants | F1: Cancer history | G1: NumberOfMajorSurgeries | H1: smoker | J1: Customer ID | K1: BMI | L1: Weight Status | M1: HBA1C | N1: Diabetes Status | O1: Heart Issues | P1: Any Transplants | Q1: Cancer history | R1: NumberOfMajorSurgeries | S1: smoker
A2: Id1 | B2: 47.41 | C2: 7.47 | D2: No | E2: No | F2: No | G2: No major surgery | H2: yes | J2: Id1 | K2: 47.41 | L2: =IF(K2< 18.5, "under weight",IF(K2<24.9,"normal weight",IF(K2<29.9,"over weight","obeisity"))) -> obeisity | M2: 7.47 | N2: =IF(M2<5.7,"normal",IF(M2<6.4,"prediabets",IF(M2>6.4-6.5,"diabetes"))) -> diabetes | O2: No | P2: No | Q2: No | R2: 0 | S2: Yes
A3: Id2 | B3: 30.36 | C3: 5.77 | D3: No | E3: No | F3: No | G3: No major surgery | H3: yes | J3: Id2 | K3: 30.36 | L3: =IF(K3< 18.5, "under weight",IF(K3<24.9,"normal weight",IF(K3<29.9,"over weight","obeisity"))) -> obeisity | M3: 5.77 | N3: =IF(M3<5.7,"normal",IF(M3<6.4,"prediabets",IF(M3>6.4-6.5,"diabetes"))) -> prediabets | O3: No | P3: No | Q3: No | R3: 0 | S3: Yes
A4: Id3 | B4: 34.485 | C4: 11.87 | D4: yes | E4: No | F4: No | G4: 2 | H4: yes | J4: Id3 | K4: 34.485 | L4: =IF(K4< 18.5, "under weight",IF(K4<24.9,"normal weight",IF(K4<29.9,"over weight","obeisity"))) -> obeisity | M4: 11.87 | N4: =IF(M4<5.7,"normal",IF(M4<6.4,"prediabets",IF(M4>6.4-6.5,"diabetes"))) -> diabetes | O4: Yes | P4: No | Q4: No | R4: 2 | S4: Yes
A5: Id4 | B5: 38.095 | C5: 6.05 | D5: No | E5: No | F5: No | G5: No major surgery | H5: yes | J5: Id4 | K5: 38.095 | L5: =IF(K5< 18.5, "under weight",IF(K5<24.9,"normal weight",IF(K5<29.9,"over weight","obeisity"))) -> obeisity | M5: 6.05 | N5: =IF(M5<5.7,"normal",IF(M5<6.4,"prediabets",IF(M5>6.4-6.5,"diabetes"))) -> prediabets | O5: No | P5: No | Q5: No | R5: 0 | S5: Yes
A6: Id5 | B6: 35.53 | C6: 5.45 | D6: No | E6: No | F6: No | G6: No major surgery | H6: yes | J6: Id5 | K6: 35.53 | L6: =IF(K6< 18.5, "under weight",IF(K6<24.9,"normal weight",IF(K6<29.9,"over weight","obeisity"))) -> obeisity | M6: 5.45 | N6: =IF(M6<5.7,"normal",IF(M6<6.4,"prediabets",IF(M6>6.4-6.5,"diabetes"))) -> normal | O6: No | P6: No | Q6: No | R6: 0 | S6: Yes
A7: Id6 | B7: 32.8 | C7: 6.59 | D7: No | E7: No | F7: No | G7: No major surgery | H7: yes | J7: Id6 | K7: 32.8 | L7: =IF(K7< 18.5, "under weight",IF(K7<24.9,"normal weight",IF(K7<29.9,"over weight","obeisity"))) -> obeisity | M7: 6.59 | N7: =IF(M7<5.7,"normal",IF(M7<6.4,"prediabets",IF(M7>6.4-6.5,"diabetes"))) -> diabetes | O7: No | P7: No | Q7: No | R7: 0 | S7: Yes
A8: Id7 | B8: 36.4 | C8: 6.07 | D8: No | E8: No | F8: No | G8: No major surgery | H8: yes | J8: Id7 | K8: 36.4 | L8: =IF(K8< 18.5, "under weight",IF(K8<24.9,"normal weight",IF(K8<29.9,"over weight","obeisity"))) -> obeisity | M8: 6.07 | N8: =IF(M8<5.7,"normal",IF(M8<6.4,"prediabets",IF(M8>6.4-6.5,"diabetes"))) -> prediabets | O8: No | P8: No | Q8: No | R8: 0 | S8: Yes
A9: Id8 | B9: 36.96 | C9: 7.93 | D9: No | E9: No | F9: No | G9: 3 | H9: yes | J9: Id8 | K9: 36.96 | L9: =IF(K9< 18.5, "under weight",IF(K9<24.9,"normal weight",IF(K9<29.9,"over weight","obeisity"))) -> obeisity | M9: 7.93 | N9: =IF(M9<5.7,"normal",IF(M9<6.4,"prediabets",IF(M9>6.4-6.5,"diabetes"))) -> diabetes | O9: No | P9: No | Q9: No | R9: 3 | S9: Yes
A10: Id9 | B10: 41.14 | C10: 9.58 | D10: yes | E10: No | F10: Yes | G10: 1 | H10: yes | J10: Id9 | K10: 41.14 | L10: =IF(K10< 18.5, "under weight",IF(K10<24.9,"normal weight",IF(K10<29.9,"over weight","obeisity"))) -> obeisity | M10: 9.58 | N10: =IF(M10<5.7,"normal",IF(M10<6.4,"prediabets",IF(M10>6.4-6.5,"diabetes"))) -> diabetes | O10: Yes | P10: No | Q10: Yes | R10: 1 | S10: Yes
A11: Id10 | B11: 38.06 | C11: 10.79 | D11: No | E11: No | F11: No | G11: No major surgery | H11: yes | J11: Id10 | K11: 38.06 | L11: =IF(K11< 18.5, "under weight",IF(K11<24.9,"normal weight",IF(K11<29.9,"over weight","obeisity"))) -> obeisity | M11: 10.79 | N11: =IF(M11<5.7,"normal",IF(M11<6.4,"prediabets",IF(M11>6.4-6.5,"diabetes"))) -> diabetes | O11: No | P11: No | Q11: No | R11: 0 | S11: Yes
A12: Id11 | B12: 37.7 | C12: 5.96 | D12: yes | E12: No | F12: No | G12: 2 | H12: yes | J12: Id11 | K12: 37.7 | L12: =IF(K12< 18.5, "under weight",IF(K12<24.9,"normal weight",IF(K12<29.9,"over weight","obeisity"))) -> obeisity | M12: 5.96 | N12: =IF(M12<5.7,"normal",IF(M12<6.4,"prediabets",IF(M12>6.4-6.5,"diabetes"))) -> prediabets | O12: Yes | P12: No | Q12: No | R12: 2 | S12: Yes
A13: Id12 | B13: 42.13 | C13: 11.9 | D13: No | E13: No | F13: No | G13: No major surgery | H13: yes | J13: Id12 | K13: 42.13 | L13: =IF(K13< 18.5, "under weight",IF(K13<24.9,"normal weight",IF(K13<29.9,"over weight","obeisity"))) -> obeisity | M13: 11.9 | N13: =IF(M13<5.7,"normal",IF(M13<6.4,"prediabets",IF(M13>6.4-6.5,"diabetes"))) -> diabetes | O13: No | P13: No | Q13: No | R13: 0 | S13: Yes
A14: Id13 | B14: 40.92 | C14: 8.41 | D14: No | E14: No | F14: No | G14: No major surgery | H14: yes | J14: Id13 | K14: 40.92 | L14: =IF(K14< 18.5, "under weight",IF(K14<24.9,"normal weight",IF(K14<29.9,"over weight","obeisity"))) -> obeisity | M14: 8.41 | N14: =IF(M14<5.7,"normal",IF(M14<6.4,"prediabets",IF(M14>6.4-6.5,"diabetes"))) -> diabetes | O14: No | P14: No | Q14: No | R14: 0 | S14: Yes
A15: Id14 | B15: 40.565 | C15: 7.02 | D15: No | E15: No | F15: No | G15: No major surgery | H15: yes | J15: Id14 | K15: 40.565 | L15: =IF(K15< 18.5, "under weight",IF(K15<24.9,"normal weight",IF(K15<29.9,"over weight","obeisity"))) -> obeisity | M15: 7.02 | N15: =IF(M15<5.7,"normal",IF(M15<6.4,"prediabets",IF(M15>6.4-6.5,"diabetes"))) -> diabetes | O15: No | P15: No | Q15: No | R15: 0 | S15: Yes
A16: Id15 | B16: 36.385 | C16: 7.59 | D16: yes | E16: No | F16: No | G16: 2 | H16: yes | J16: Id15 | K16: 36.385 | L16: =IF(K16< 18.5, "under weight",IF(K16<24.9,"normal weight",IF(K16<29.9,"over weight","obeisity"))) -> obeisity | M16: 7.59 | N16: =IF(M16<5.7,"normal",IF(M16<6.4,"prediabets",IF(M16>6.4-6.5,"diabetes"))) -> diabetes | O16: Yes | P16: No | Q16: No | R16: 2 | S16: Yes
A17: Id16 | B17: 39.9 | C17: 11.32 | D17: No | E17: No | F17: No | G17: No major surgery | H17: yes | J17: Id16 | K17: 39.9 | L17: =IF(K17< 18.5, "under weight",IF(K17<24.9,"normal weight",IF(K17<29.9,"over weight","obeisity"))) -> obeisity | M17: 11.32 | N17: =IF(M17<5.7,"normal",IF(M17<6.4,"prediabets",IF(M17>6.4-6.5,"diabetes"))) -> diabetes | O17: No | P17: No | Q17: No | R17: 0 | S17: Yes
A18: Id17 | B18: 33.8 | C18: 7.67 | D18: No | E18: No | F18: No | G18: 3 | H18: yes | J18: Id17 | K18: 33.8 | L18: =IF(K18< 18.5, "under weight",IF(K18<24.9,"normal weight",IF(K18<29.9,"over weight","obeisity"))) -> obeisity | M18: 7.67 | N18: =IF(M18<5.7,"normal",IF(M18<6.4,"prediabets",IF(M18>6.4-6.5,"diabetes"))) -> diabetes | O18: No | P18: No | Q18: No | R18: 3 | S18: Yes
A19: Id18 | B19: 36.765 | C19: 7.29 | D19: yes | E19: No | F19: Yes | G19: 1 | H19: yes | J19: Id18 | K19: 36.765 | L19: =IF(K19< 18.5, "under weight",IF(K19<24.9,"normal weight",IF(K19<29.9,"over weight","obeisity"))) -> obeisity | M19: 7.29 | N19: =IF(M19<5.7,"normal",IF(M19<6.4,"prediabets",IF(M19>6.4-6.5,"diabetes"))) -> diabetes | O19: Yes | P19: No | Q19: Yes | R19: 1 | S19: Yes
A20: Id19 | B20: 36.955 | C20: 4.72 | D20: yes | E20: No | F20: No | G20: 1 | H20: yes | J20: Id19 | K20: 36.955 | L20: =IF(K20< 18.5, "under weight",IF(K20<24.9,"normal weight",IF(K20<29.9,"over weight","obeisity"))) -> obeisity | M20: 4.72 | N20: =IF(M20<5.7,"normal",IF(M20<6.4,"prediabets",IF(M20>6.4-6.5,"diabetes"))) -> normal | O20: Yes | P20: No | Q20: No | R20: 1 | S20: Yes
A21: Id20 | B21: 42.9 | C21: 11.41 | D21: No | E21: No | F21: No | G21: No major surgery | H21: yes | J21: Id20 | K21: 42.9 | L21: =IF(K21< 18.5, "under weight",IF(K21<24.9,"normal weight",IF(K21<29.9,"over weight","obeisity"))) -> obeisity | M21: 11.41 | N21: =IF(M21<5.7,"normal",IF(M21<6.4,"prediabets",IF(M21>6.4-6.5,"diabetes"))) -> diabetes | O21: No | P21: No | Q21: No | R21: 0 | S21: Yes
A22: Id21 | B22: 36.3 | C22: 11.5 | D22: yes | E22: No | F22: No | G22: 2 | H22: yes | J22: Id21 | K22: 36.3 | L22: =IF(K22< 18.5, "under weight",IF(K22<24.9,"normal weight",IF(K22<29.9,"over weight","obeisity"))) -> obeisity | M22: 11.5 | N22: =IF(M22<5.7,"normal",IF(M22<6.4,"prediabets",IF(M22>6.4-6.5,"diabetes"))) -> diabetes | O22: Yes | P22: No | Q22: No | R22: 2 | S22: Yes
A23: Id22 | B23: 32.2 | C23: 6.22 | D23: yes | E23: No | F23: No | G23: 2 | H23: yes | J23: Id22 | K23: 32.2 | L23: =IF(K23< 18.5, "under weight",IF(K23<24.9,"normal weight",IF(K23<29.9,"over weight","obeisity"))) -> obeisity | M23: 6.22 | N23: =IF(M23<5.7,"normal",IF(M23<6.4,"prediabets",IF(M23>6.4-6.5,"diabetes"))) -> prediabets | O23: Yes | P23: No | Q23: No | R23: 2 | S23: Yes
A24: Id23 | B24: 31.3 | C24: 11.38 | D24: No | E24: No | F24: No | G24: 3 | H24: yes | J24: Id23 | K24: 31.3 | L24: =IF(K24< 18.5, "under weight",IF(K24<24.9,"normal weight",IF(K24<29.9,"over weight","obeisity"))) -> obeisity | M24: 11.38 | N24: =IF(M24<5.7,"normal",IF(M24<6.4,"prediabets",IF(M24>6.4-6.5,"diabetes"))) -> diabetes | O24: No | P24: No | Q24: No | R24: 3 | S24: Yes
A25: Id24 | B25: 41.8 | C25: 7.89 | D25: yes | E25: No | F25: No | G25: 2 | H25: yes | J25: Id24 | K25: 41.8 | L25: =IF(K25< 18.5, "under weight",IF(K25<24.9,"normal weight",IF(K25<29.9,"over weight","obeisity"))) -> obeisity | M25: 7.89 | N25: =IF(M25<5.7,"normal",IF(M25<6.4,"prediabets",IF(M25>6.4-6.5,"diabetes"))) -> diabetes | O25: Yes | P25: No | Q25: No | R25: 2 | S25: Yes
A26: Id25 | B26: 35.09 | C26: 4.38 | D26: yes | E26: No | F26: No | G26: 2 | H26: yes | J26: Id25 | K26: 35.09 | L26: =IF(K26< 18.5, "under weight",IF(K26<24.9,"normal weight",IF(K26<29.9,"over weight","obeisity"))) -> obeisity | M26: 4.38 | N26: =IF(M26<5.7,"normal",IF(M26<6.4,"prediabets",IF(M26>6.4-6.5,"diabetes"))) -> normal | O26: Yes | P26: No | Q26: No | R26: 2 | S26: Yes
A27: Id26 | B27: 33.88 | C27: 7.01 | D27: No | E27: No | F27: No | G27: 3 | H27: yes | J27: Id26 | K27: 33.88 | L27: =IF(K27< 18.5, "under weight",IF(K27<24.9,"normal weight",IF(K27<29.9,"over weight","obeisity"))) -> obeisity | M27: 7.01 | N27: =IF(M27<5.7,"normal",IF(M27<6.4,"prediabets",IF(M27>6.4-6.5,"diabetes"))) -> diabetes | O27: No | P27: No | Q27: No | R27: 3 | S27: Yes
A28: Id27 | B28: 30.875 | C28: 11.88 | D28: No | E28: No | F28: No | G28: No major surgery | H28: yes | J28: Id27 | K28: 30.875 | L28: =IF(K28< 18.5, "under weight",IF(K28<24.9,"normal weight",IF(K28<29.9,"over weight","obeisity"))) -> obeisity | M28: 11.88 | N28: =IF(M28<5.7,"normal",IF(M28<6.4,"prediabets",IF(M28>6.4-6.5,"diabetes"))) -> diabetes | O28: No | P28: No | Q28: No | R28: 0 | S28: Yes
A29: Id28 | B29: 36.86 | C29: 5.19 | D29: yes | E29: No | F29: Yes | G29: 1 | H29: yes | J29: Id28 | K29: 36.86 | L29: =IF(K29< 18.5, "under weight",IF(K29<24.9,"normal weight",IF(K29<29.9,"over weight","obeisity"))) -> obeisity | M29: 5.19 | N29: =IF(M29<5.7,"normal",IF(M29<6.4,"prediabets",IF(M29>6.4-6.5,"diabetes"))) -> normal | O29: Yes | P29: No | Q29: Yes | R29: 1 | S29: Yes
A30: Id29 | B30: 35.86 | C30: 6.74 | D30: yes | E30: No | F30: No | G30: 2 | H30: yes | J30: Id29 | K30: 35.86 | L30: =IF(K30< 18.5, "under weight",IF(K30<24.9,"normal weight",IF(K30<29.9,"over weight","obeisity"))) -> obeisity | M30: 6.74 | N30: =IF(M30<5.7,"normal",IF(M30<6.4,"prediabets",IF(M30>6.4-6.5,"diabetes"))) -> diabetes | O30: Yes | P30: No | Q30: No | R30: 2 | S30: Yes
A31: Id30 | B31: 37.05 | C31: 8.44 | D31: No | E31: No | F31: No | G31: No major surgery | H31: yes | J31: Id30 | K31: 37.05 | L31: =IF(K31< 18.5, "under weight",IF(K31<24.9,"normal weight",IF(K31<29.9,"over weight","obeisity"))) -> obeisity | M31: 8.44 | N31: =IF(M31<5.7,"normal",IF(M31<6.4,"prediabets",IF(M31>6.4-6.5,"diabetes"))) -> diabetes | O31: No | P31: No | Q31: No | R31: 0 | S31: Yes
A32: Id31 | B32: 43.89 | C32: 8.71 | D32: No | E32: No | F32: No | G32: No major surgery | H32: yes | J32: Id31 | K32: 43.89 | L32: =IF(K32< 18.5, "under weight",IF(K32<24.9,"normal weight",IF(K32<29.9,"over weight","obeisity"))) -> obeisity | M32: 8.71 | N32: =IF(M32<5.7,"normal",IF(M32<6.4,"prediabets",IF(M32>6.4-6.5,"diabetes"))) -> diabetes | O32: No | P32: No | Q32: No | R32: 0 | S32: Yes
A33: Id32 | B33: 42.35 | C33: 5.08 | D33: yes | E33: No | F33: No | G33: No major surgery | H33: yes | J33: Id32 | K33: 42.35 | L33: =IF(K33< 18.5, "under weight",IF(K33<24.9,"normal weight",IF(K33<29.9,"over weight","obeisity"))) -> obeisity | M33: 5.08 | N33: =IF(M33<5.7,"normal",IF(M33<6.4,"prediabets",IF(M33>6.4-6.5,"diabetes"))) -> normal | O33: Yes | P33: No | Q33: No | R33: 0 | S33: Yes
A34: Id33 | B34: 31.35 | C34: 6.86 | D34: No | E34: No | F34: No | G34: No major surgery | H34: yes | J34: Id33 | K34: 31.35 | L34: =IF(K34< 18.5, "under weight",IF(K34<24.9,"normal weight",IF(K34<29.9,"over weight","obeisity"))) -> obeisity | M34: 6.86 | N34: =IF(M34<5.7,"normal",IF(M34<6.4,"prediabets",IF(M34>6.4-6.5,"diabetes"))) -> diabetes | O34: No | P34: No | Q34: No | R34: 0 | S34: Yes
A35: Id34 | B35: 47.6 | C35: 5.95 | D35: yes | E35: No | F35: No | G35: No major surgery | H35: yes | J35: Id34 | K35: 47.6 | L35: =IF(K35< 18.5, "under weight",IF(K35<24.9,"normal weight",IF(K35<29.9,"over weight","obeisity"))) -> obeisity | M35: 5.95 | N35: =IF(M35<5.7,"normal",IF(M35<6.4,"prediabets",IF(M35>6.4-6.5,"diabetes"))) -> prediabets | O35: Yes | P35: No | Q35: No | R35: 0 | S35: Yes
A36: Id35 | B36: 46.2 | C36: 6.09 | D36: No | E36: No | F36: Yes | G36: 1 | H36: yes | J36: Id35 | K36: 46.2 | L36: =IF(K36< 18.5, "under weight",IF(K36<24.9,"normal weight",IF(K36<29.9,"over weight","obeisity"))) -> obeisity | M36: 6.09 | N36: =IF(M36<5.7,"normal",IF(M36<6.4,"prediabets",IF(M36>6.4-6.5,"diabetes"))) -> prediabets | O36: No | P36: No | Q36: Yes | R36: 1 | S36: Yes
A37: Id36 | B37: 32.015 | C37: 11.75 | D37: No | E37: No | F37: No | G37: No major surgery | H37: yes | J37: Id36 | K37: 32.015 | L37: =IF(K37< 18.5, "under weight",IF(K37<24.9,"normal weight",IF(K37<29.9,"over weight","obeisity"))) -> obeisity | M37: 11.75 | N37: =IF(M37<5.7,"normal",IF(M37<6.4,"prediabets",IF(M37>6.4-6.5,"diabetes"))) -> diabetes | O37: No | P37: No | Q37: No | R37: 0 | S37: Yes
A38: Id37 | B38: 40.565 | C38: 7.37 | D38: No | E38: No | F38: No | G38: No major surgery | H38: yes | J38: Id37 | K38: 40.565 | L38: =IF(K38< 18.5, "under weight",IF(K38<24.9,"normal weight",IF(K38<29.9,"over weight","obeisity"))) -> obeisity | M38: 7.37 | N38: =IF(M38<5.7,"normal",IF(M38<6.4,"prediabets",IF(M38>6.4-6.5,"diabetes"))) -> diabetes | O38: No | P38: No | Q38: No | R38: 0 | S38: Yes
A39: Id38 | B39: 32.45 | C39: 11.91 | D39: No | E39: No | F39: No | G39: No major surgery | H39: yes | J39: Id38 | K39: 32.45 | L39: =IF(K39< 18.5, "under weight",IF(K39<24.9,"normal weight",IF(K39<29.9,"over weight","obeisity"))) -> obeisity | M39: 11.91 | N39: =IF(M39<5.7,"normal",IF(M39<6.4,"prediabets",IF(M39>6.4-6.5,"diabetes"))) -> diabetes | O39: No | P39: No | Q39: No | R39: 0 | S39: Yes
A40: Id39 | B40: 34.96 | C40: 6.52 | D40: No | E40: No | F40: No | G40: No major surgery | H40: yes | J40: Id39 | K40: 34.96 | L40: =IF(K40< 18.5, "under weight",IF(K40<24.9,"normal weight",IF(K40<29.9,"over weight","obeisity"))) -> obeisity | M40: 6.52 | N40: =IF(M40<5.7,"normal",IF(M40<6.4,"prediabets",IF(M40>6.4-6.5,"diabetes"))) -> diabetes | O40: No | P40: No | Q40: No | R40: 0 | S40: Yes
...

Sheet Hospitalisation Details
A1: Customer ID | B1: year | C1: month | D1: date | E1: children | F1: charges | G1: Hospital tier | H1: City tier | I1: State ID | K1: Column1 | L1: Date Of Birth | M1: Age | N1: children | O1: charges | P1: Hospital tier | Q1: City tier | R1: State ID
A2: Id2335 | B2: 1992 | C2: Jul | D2: 9 | E2: 0 | F2: 563.84 | G2: tier - 2 | H2: tier - 3 | I2: R1013 | K2: Id2335 | L2: 33794 | M2: =DATEDIF(L2,DATE(2023,6,8),"y") -> 30 | N2: 0 | O2: 563.84 | P2: tier - 2 | Q2: tier - 3 | R2: R1013
A3: Id2334 | B3: 1992 | C3: Nov | D3: 30 | E3: 0 | F3: 570.62 | G3: tier - 2 | H3: tier - 1 | I3: R1013 | K3: Id2334 | L3: 33938 | M3: =DATEDIF(L3,DATE(2023,6,8),"y") -> 30 | N3: 0 | O3: 570.62 | P3: tier - 2 | Q3: tier - 1 | R3: R1013
A4: Id2333 | B4: 1993 | C4: Jun | D4: 30 | E4: 0 | F4: 600 | G4: tier - 2 | H4: tier - 1 | I4: R1013 | K4: Id2333 | L4: 34150 | M4: =DATEDIF(L4,DATE(2023,6,8),"y") -> 29 | N4: 0 | O4: 600 | P4: tier - 2 | Q4: tier - 1 | R4: R1013
A5: Id2332 | B5: 1992 | C5: Sep | D5: 13 | E5: 0 | F5: 604.54 | G5: tier - 3 | H5: tier - 3 | I5: R1013 | K5: Id2332 | L5: 33860 | M5: =DATEDIF(L5,DATE(2023,6,8),"y") -> 30 | N5: 0 | O5: 604.54 | P5: tier - 3 | Q5: tier - 3 | R5: R1013
A6: Id2331 | B6: 1998 | C6: Jul | D6: 27 | E6: 0 | F6: 637.26 | G6: tier - 3 | H6: tier - 3 | I6: R1013 | K6: Id2331 | L6: 36003 | M6: =DATEDIF(L6,DATE(2023,6,8),"y") -> 24 | N6: 0 | O6: 637.26 | P6: tier - 3 | Q6: tier - 3 | R6: R1013
A7: Id2330 | B7: 2001 | C7: Nov | D7: 20 | E7: 0 | F7: 646.14 | G7: tier - 3 | H7: tier - 3 | I7: R1012 | K7: Id2330 | L7: 37215 | M7: =DATEDIF(L7,DATE(2023,6,8),"y") -> 21 | N7: 0 | O7: 646.14 | P7: tier - 3 | Q7: tier - 3 | R7: R1012
A8: Id2329 | B8: 1993 | C8: Jun | D8: 1 | E8: 0 | F8: 650 | G8: tier - 3 | H8: tier - 3 | I8: R1013 | K8: Id2329 | L8: 34121 | M8: =DATEDIF(L8,DATE(2023,6,8),"y") -> 30 | N8: 0 | O8: 650 | P8: tier - 3 | Q8: tier - 3 | R8: R1013
A9: Id2328 | B9: 1995 | C9: Jul | D9: 4 | E9: 0 | F9: 650 | G9: tier - 3 | H9: tier - 3 | I9: R1013 | K9: Id2328 | L9: 34884 | M9: =DATEDIF(L9,DATE(2023,6,8),"y") -> 27 | N9: 0 | O9: 650 | P9: tier - 3 | Q9: tier - 3 | R9: R1013
A10: Id2327 | B10: 2002 | C10: Nov | D10: 29 | E10: 0 | F10: 668 | G10: tier - 3 | H10: tier - 2 | I10: R1012 | K10: Id2327 | L10: 37589 | M10: =DATEDIF(L10,DATE(2023,6,8),"y") -> 20 | N10: 0 | O10: 668 | P10: tier - 3 | Q10: tier - 2 | R10: R1012
A11: Id2326 | B11: 1997 | C11: Nov | D11: 9 | E11: 0 | F11: 670 | G11: tier - 3 | H11: tier - 3 | I11: R1013 | K11: Id2326 | L11: 35743 | M11: =DATEDIF(L11,DATE(2023,6,8),"y") -> 25 | N11: 0 | O11: 670 | P11: tier - 3 | Q11: tier - 3 | R11: R1013
A12: Id2325 | B12: 2001 | C12: Sep | D12: 12 | E12: 0 | F12: 687.54 | G12: tier - 3 | H12: tier - 2 | I12: R1013 | K12: Id2325 | L12: 37146 | M12: =DATEDIF(L12,DATE(2023,6,8),"y") -> 21 | N12: 0 | O12: 687.54 | P12: tier - 3 | Q12: tier - 2 | R12: R1013
A13: Id2324 | B13: 1999 | C13: Dec | D13: 26 | E13: 0 | F13: 700 | G13: ? | H13: tier - 3 | I13: R1013 | K13: Id2324 | L13: 36520 | M13: =DATEDIF(L13,DATE(2023,6,8),"y") -> 23 | N13: 0 | O13: 700 | P13: tier-3 | Q13: tier - 3 | R13: R1013
... A1050: Id1290 | B1050: 1977 | C1050: Jul | D1050: 26 | E1050: 2 | F1050: 8527.53 | G1050: tier - 2 | H1050: tier - 2 | I1050: R1013 | K1050: Id1287 | L1050: 27704 | M1050: =DATEDIF(L1050,DATE(2023,6,8),"y") -> 47 | N1050: 1 | O1050: 8539.67 | P1050: tier - 2 | Q1050: tier - 3 | R1050: R1011
A1051: Id1289 | B1051: ? | C1051: Jul | D1051: 24 | E1051: 0 | F1051: 8534.67 | G1051: tier - 2 | H1051: tier - 3 | I1051: R1024 | K1051: Id1286 | L1051: 38698 | M1051: =DATEDIF(L1051,DATE(2023,6,8),"y") -> 17 | N1051: 1 | O1051: 8547.69 | P1051: tier - 2 | Q1051: tier - 1 | R1051: R1013
A1052: Id1288 | B1052: 1981 | C1052: Dec | D1052: 27 | E1052: 3 | F1052: 8538.29 | G1052: tier - 2 | H1052: tier - 3 | I1052: R1024 | K1052: Id1285 | L1052: 27612 | M1052: =DATEDIF(L1052,DATE(2023,6,8),"y") -> 47 | N1052: 1 | O1052: 8551.35 | P1052: tier - 2 | Q1052: tier - 2 | R1052: R1011
A1053: Id1287 | B1053: 1975 | C1053: Nov | D1053: 6 | E1053: 1 | F1053: 8539.67 | G1053: tier - 2 | H1053: tier - 3 | I1053: R1011 | K1053: Id1284 | L1053: 27627 | M1053: =DATEDIF(L1053,DATE(2023,6,8),"y") -> 47 | N1053: 1 | O1053: 8556.91 | P1053: tier - 2 | Q1053: tier - 1 | R1053: R1011
A1054: Id1286 | B1054: ? | C1054: Dec | D1054: 12 | E1054: 1 | F1054: 8547.69 | G1054: tier - 2 | H1054: tier - 1 | I1054: R1013 | K1054: Id1283 | L1054: 32407 | M1054: =DATEDIF(L1054,DATE(2023,6,8),"y") -> 34 | N1054: 3 | O1054: 8567.25 | P1054: tier - 2 | Q1054: tier - 1 | R1054: R1012
A1055: Id1285 | B1055: 1975 | C1055: Aug | D1055: 6 | E1055: 1 | F1055: 8551.35 | G1055: tier - 2 | H1055: tier - 2 | I1055: R1011 | K1055: Id1282 | L1055: 27663 | M1055: =DATEDIF(L1055,DATE(2023,6,8),"y") -> 47 | N1055: 1 | O1055: 8569.86 | P1055: tier - 2 | Q1055: tier - 3 | R1055: R1013
A1056: Id1284 | B1056: 1975 | C1056: Aug | D1056: 21 | E1056: 1 | F1056: 8556.91 | G1056: tier - 2 | H1056: tier - 1 | I1056: R1011 | K1056: Id1281 | L1056: 30291 | M1056: =DATEDIF(L1056,DATE(2023,6,8),"y") -> 40 | N1056: 3 | O1056: 8572.04 | P1056: tier - 2 | Q1056: tier - 2 | R1056: R1021
A1057: Id1283 | B1057: 1988 | C1057: Sep | D1057: 21 | E1057: 3 | F1057: 8567.25 | G1057: tier - 2 | H1057: tier - 1 | I1057: R1012 | K1057: Id1280 | L1057: 32092 | M1057: =DATEDIF(L1057,DATE(2023,6,8),"y") -> 35 | N1057: 3 | O1057: 8573.3 | P1057: tier - 2 | Q1057: tier - 2 | R1057: R1021
A1058: Id1282 | B1058: 1975 | C1058: Sep | D1058: 26 | E1058: 1 | F1058: 8569.86 | G1058: tier - 2 | H1058: tier - 3 | I1058: R1013 | K1058: Id1279 | L1058: 30680 | M1058: =DATEDIF(L1058,DATE(2023,6,8),"y") -> 39 | N1058: 5 | O1058: 8582.3 | P1058: tier - 2 | Q1058: tier - 1 | R1058: R1013
A1059: Id1281 | B1059: 1982 | C1059: Dec | D1059: 6 | E1059: 3 | F1059: 8572.04 | G1059: tier - 2 | H1059: tier - 2 | I1059: R1021 | K1059: Id1278 | L1059: 30522 | M1059: =DATEDIF(L1059,DATE(2023,6,8),"y") -> 39 | N1059: 5 | O1059: 8596.83 | P1059: tier - 2 | Q1059: tier - 3 | R1059: R1013
A1060: Id1280 | B1060: 1987 | C1060: Nov | D1060: 11 | E1060: 3 | F1060: 8573.3 | G1060: tier - 2 | H1060: tier - 2 | I1060: R1021 | K1060: Id1277 | L1060: 26856 | M1060: =DATEDIF(L1060,DATE(2023,6,8),"y") -> 49 | N1060: 0 | O1060: 8601.33 | P1060: tier - 2 | Q1060: tier - 1 | R1060: R1013
A1061: Id1279 | B1061: 1983 | C1061: Dec | D1061: 30 | E1061: 5 | F1061: 8582.3 | G1061: tier - 2 | H1061: tier - 1 | I1061: R1013 | K1061: Id1276 | L1061: 28392 | M1061: =DATEDIF(L1061,DATE(2023,6,8),"y") -> 45 | N1061: 2 | O1061: 8603.82 | P1061: tier - 2 | Q1061: tier - 1 | R1061: R1019
A1062: Id1278 | B1062: 1983 | C1062: Jul | D1062: 25 | E1062: 5 | F1062: 8596.83 | G1062: tier - 2 | H1062: tier - 3 | I1062: R1013 | K1062: Id1275 | L1062: 28441 | M1062: =DATEDIF(L1062,DATE(2023,6,8),"y") -> 45 | N1062: 2 | O1062: 8604.48 | P1062: tier - 3 | Q1062: tier - 2 | R1062: R1016
A1063: Id1277 | B1063: 1973 | C1063: Jul | D1063: 11 | E1063: 0 | F1063: 8601.33 | G1063: tier - 2 | H1063: tier - 1 | I1063: R1013 | K1063: Id1274 | L1063: 28413 | M1063: =DATEDIF(L1063,DATE(2023,6,8),"y") -> 45 | N1063: 3 | O1063: 8605.36 | P1063: tier - 2 | Q1063: tier - 2 | R1063: R1013
A1064: Id1276 | B1064: 1977 | C1064: Sep | D1064: 24 | E1064: 2 | F1064: 8603.82 | G1064: tier - 2 | H1064: tier - 1 | I1064: R1019 | K1064: Id1273 | L1064: 29053 | M1064: =DATEDIF(L1064,DATE(2023,6,8),"y") -> 43 | N1064: 3 | O1064: 8606.22 | P1064: tier - 1 | Q1064: tier - 2 | R1064: R1014
A1065: Id1275 | B1065: 1977 | C1065: Nov | D1065: 12 | E1065: 2 | F1065: 8604.48 | G1065: tier - 3 | H1065: tier - 2 | I1065: R1016 | K1065: Id1272 | L1065: 28370 | M1065: =DATEDIF(L1065,DATE(2023,6,8),"y") -> 45 | N1065: 3 | O1065: 8615.3 | P1065: tier - 2 | Q1065: tier - 3 | R1065: R1011
A1066: Id1274 | B1066: 1977 | C1066: Oct | D1066: 15 | E1066: 3 | F1066: 8605.36 | G1066: tier - 2 | H1066: tier - 2 | I1066: R1013 | K1066: Id1271 | L1066: 27609 | M1066: =DATEDIF(L1066,DATE(2023,6,8),"y") -> 47 | N1066: 1 | O1066: 8627.54 | P1066: tier - 2 | Q1066: tier - 2 | R1066: R1017
... A2338: Id7 | B2338: 1994 | C2338: Oct | D2338: 27 | E2338: 1 | F2338: 51194.56 | G2338: tier - 1 | H2338: tier - 3 | I2338: R1011 | K2338: Id1 | L2338: 25123 | M2338: =DATEDIF(L2338,DATE(2023,6,8),"y") -> 54 | N2338: 0 | O2338: 63770.43 | P2338: tier - 1 | Q2338: tier - 3 | R2338: R1013
A2339: Id6 | B2339: 1962 | C2339: Aug | D2339: 4 | E2339: 0 | F2339: 52590.83 | G2339: tier - 1 | H2339: tier - 3 | I2339: R1011
A2340: Id5 | B2340: 1989 | C2340: Jun | D2340: 19 | E2340: 0 | F2340: 55135.4 | G2340: tier - 1 | H2340: tier - 2 | I2340: R1012
A2341: Id4 | B2341: 1991 | C2341: Jun | D2341: 6 | E2341: 1 | F2341: 58571.07 | G2341: tier - 1 | H2341: tier - 3 | I2341: R1024
A2342: Id3 | B2342: 1970 | C2342: ? | D2342: 11 | E2342: 3 | F2342: 60021.4 | G2342: tier - 1 | H2342: tier - 1 | I2342: R1012
A2343: Id2 | B2343: 1977 | C2343: Jun | D2343: 8 | E2343: 0 | F2343: 62592.87 | G2343: tier - 2 | H2343: tier - 3 | I2343: R1013
A2344: Id1 | B2344: 1968 | C2344: Oct | D2344: 12 | E2344: 0 | F2344: 63770.43 | G2344: tier - 1 | H2344: tier - 3 | I2344: R1013

Sheet Health Care
A1: Customer ID | B1: Title | C1: First Name | D1: Last Name | E1: BMI | F1: Weight Status | G1: HBA1C | H1: Diabetes Status | I1: Heart Issues | J1: Any Transplants | K1: Cancer history | L1: NumberOfMajorSurgeries | M1: smoker | N1: Date Of Birth | O1: Age | P1: children | Q1: charges | R1: Hospital tier | S1: City tier | T1: State ID
A2: Id1 | B2: {=VLOOKUP(A2,'Customer Names'!$E$2:$H$2336,{2,3,4},0)} -> Ms | C2: Kelly | D2: Hawks | E2: {=VLOOKUP(A2,'Medical Examinations'!$J$2:$S$2336,{2,3,4,5,6,7,8,9,10},0)} -> 47.41 | F2: obeisity | G2: 7.47 | H2: diabetes | I2: No | J2: No | K2: No | L2: 0 | M2: Yes | N2: {=VLOOKUP(A2,'Hospitalisation Details'!$K$2:$R$2338,{2,3,4,5,6,7,8},0)} -> 25123 | O2: 54 | P2: 0 | Q2: 63770.43 | R2: tier - 1 | S2: tier - 3 | T2: R1013
A3: Id2 | B3: {=VLOOKUP(A3,'Customer Names'!$E$2:$H$2336,{2,3,4},0)} -> Mr | C3: Matthew D | D3: Lehner | E3: {=VLOOKUP(A3,'Medical Examinations'!$J$2:$S$2336,{2,3,4,5,6,7,8,9,10},0)} -> 30.36 | F3: obeisity | G3: 5.77 | H3: prediabets | I3: No | J3: No | K3: No | L3: 0 | M3: Yes | N3: {=VLOOKUP(A3,'Hospitalisation Details'!$K$2:$R$2338,{2,3,4,5,6,7,8},0)} -> 28284 | O3: 46 | P3: 0 | Q3: 62592.87 | R3: tier - 2 | S3: tier - 3 | T3: R1013
A4: Id3 | B4: {=VLOOKUP(A4,'Customer Names'!$E$2:$H$2336,{2,3,4},0)} -> Mr | C4: Phil | D4: Lu | E4: {=VLOOKUP(A4,'Medical Examinations'!$J$2:$S$2336,{2,3,4,5,6,7,8,9,10},0)} -> 34.485 | F4: obeisity | G4: 11.87 | H4: diabetes | I4: Yes | J4: No | K4: No | L4: 2 | M4: Yes | N4: {=VLOOKUP(A4,'Hospitalisation Details'!$K$2:$R$2338,{2,3,4,5,6,7,8},0)} -> 25822 | O4: 52 | P4: 3 | Q4: 60021.4 | R4: tier - 1 | S4: tier - 1 | T4: R1012
A5: Id4 | B5: {=VLOOKUP(A5,'Customer Names'!$E$2:$H$2336,{2,3,4},0)} -> Ms | C5: Kelsey | D5: Osborne | E5: {=VLOOKUP(A5,'Medical Examinations'!$J$2:$S$2336,{2,3,4,5,6,7,8,9,10},0)} -> 38.095 | F5: obeisity | G5: 6.05 | H5: prediabets | I5: No | J5: No | K5: No | L5: 0 | M5: Yes | N5: {=VLOOKUP(A5,'Hospitalisation Details'!$K$2:$R$2338,{2,3,4,5,6,7,8},0)} -> 33395 | O5: 32 | P5: 1 | Q5: 58571.07 | R5: tier - 1 | S5: tier - 3 | T5: R1024
A6: Id5 | B6: {=VLOOKUP(A6,'Customer Names'!$E$2:$H$2336,{2,3,4},0)} -> Ms | C6: Kristyn | D6: Kadala | E6: {=VLOOKUP(A6,'Medical Examinations'!$J$2:$S$2336,{2,3,4,5,6,7,8,9,10},0)} -> 35.53 | F6: obeisity | G6: 5.45 | H6: normal | I6: No | J6: No | K6: No | L6: 0 | M6: Yes | N6: {=VLOOKUP(A6,'Hospitalisation Details'!$K$2:$R$2338,{2,3,4,5,6,7,8},0)} -> 32678 | O6: 33 | P6: 0 | Q6: 55135.4 | R6: tier - 1 | S6: tier - 2 | T6: R1012
A7: Id6 | B7: {=VLOOKUP(A7,'Customer Names'!$E$2:$H$2336,{2,3,4},0)} -> Mr | C7: Russell B | D7: Baker | E7: {=VLOOKUP(A7,'Medical Examinations'!$J$2:$S$2336,{2,3,4,5,6,7,8,9,10},0)} -> 32.8 | F7: obeisity | G7: 6.59 | H7: diabetes | I7: No | J7: No | K7: No | L7: 0 | M7: Yes | N7: {=VLOOKUP(A7,'Hospitalisation Details'!$K$2:$R$2338,{2,3,4,5,6,7,8},0)} -> 22862 | O7: 60 | P7: 0 | Q7: 52590.83 | R7: tier - 1 | S7: tier - 3 | T7: R1011
A8: Id7 | B8: {=VLOOKUP(A8,'Customer Names'!$E$2:$H$2336,{2,3,4},0)} -> Mr | C8: Scott | D8: Macpherson | E8: {=VLOOKUP(A8,'Medical Examinations'!$J$2:$S$2336,{2,3,4,5,6,7,8,9,10},0)} -> 36.4 | F8: obeisity | G8: 6.07 | H8: prediabets | I8: No | J8: No | K8: No | L8: 0 | M8: Yes | N8: {=VLOOKUP(A8,'Hospitalisation Details'!$K$2:$R$2338,{2,3,4,5,6,7,8},0)} -> 34634 | O8: 28 | P8: 1 | Q8: 51194.56 | R8: tier - 1 | S8: tier - 3 | T8: R1011
A9: Id8 | B9: {=VLOOKUP(A9,'Customer Names'!$E$2:$H$2336,{2,3,4},0)} -> Mr | C9: Stephen | D9: Hallman | E9: {=VLOOKUP(A9,'Medical Examinations'!$J$2:$S$2336,{2,3,4,5,6,7,8,9,10},0)} -> 36.96 | F9: obeisity | G9: 7.93 | H9: diabetes | I9: No | J9: No | K9: No | L9: 3 | M9: Yes | N9: {=VLOOKUP(A9,'Hospitalisation Details'!$K$2:$R$2338,{2,3,4,5,6,7,8},0)} -> 21363 | O9: 64 | P9: 2 | Q9: 49577.66 | R9: tier - 2 | S9: tier - 2 | T9: R1013
A10: Id9 | B10: {=VLOOKUP(A10,'Customer Names'!$E$2:$H$2336,{2,3,4},0)} -> Mr | C10: Patrick R | D10: Moran | E10: {=VLOOKUP(A10,'Medical Examinations'!$J$2:$S$2336,{2,3,4,5,6,7,8,9,10},0)} -> 41.14 | F10: obeisity | G10: 9.58 | H10: diabetes | I10: Yes | J10: No | K10: Yes | L10: 1 | M10: Yes | N10: {=VLOOKUP(A10,'Hospitalisation Details'!$K$2:$R$2338,{2,3,4,5,6,7,8},0)} -> 23258 | O10: 59 | P10: 1 | Q10: 48970.25 | R10: tier - 1 | S10: tier - 2 | T10: R1013
A11: Id10 | B11: {=VLOOKUP(A11,'Customer Names'!$E$2:$H$2336,{2,3,4},0)} -> Ms | C11: Brooke N | D11: Benner | E11: {=VLOOKUP(A11,'Medical Examinations'!$J$2:$S$2336,{2,3,4,5,6,7,8,9,10},0)} -> 38.06 | F11: obeisity | G11: 10.79 | H11: diabetes | I11: No | J11: No | K11: No | L11: 0 | M11: Yes | N11: {=VLOOKUP(A11,'Hospitalisation Details'!$K$2:$R$2338,{2,3,4,5,6,7,8},0)} -> 28853 | O11: 44 | P11: 0 | Q11: 48885.14 | R11: tier - 1 | S11: tier - 2 | T11: R1013
A12: Id11 | B12: {=VLOOKUP(A12,'Customer Names'!$E$2:$H$2336,{2,3,4},0)} -> Ms | C12: Paola Andrea | D12: Fierro Vargas | E12: {=VLOOKUP(A12,'Medical Examinations'!$J$2:$S$2336,{2,3,4,5,6,7,8,9,10},0)} -> 37.7 | F12: obeisity | G12: 5.96 | H12: prediabets | I12: Yes | J12: No | K12: No | L12: 2 | M12: Yes | N12: {=VLOOKUP(A12,'Hospitalisation Details'!$K$2:$R$2338,{2,3,4,5,6,7,8},0)} -> 21753 | O12: 63 | P12: 0 | Q12: 48824.45 | R12: tier - 2 | S12: tier - 1 | T12: R1011
A13: Id12 | B13: {=VLOOKUP(A13,'Customer Names'!$E$2:$H$2336,{2,3,4},0)} -> Mr | C13: David | D13: Franz | E13: {=VLOOKUP(A13,'Medical Examinations'!$J$2:$S$2336,{2,3,4,5,6,7,8,9,10},0)} -> 42.13 | F13: obeisity | G13: 11.9 | H13: diabetes | I13: No | J13: No | K13: No | L13: 0 | M13: Yes | N13: {=VLOOKUP(A13,'Hospitalisation Details'!$K$2:$R$2338,{2,3,4,5,6,7,8},0)} -> 24042 | O13: 57 | P13: 1 | Q13: 48675.52 | R13: tier - 1 | S13: tier - 2 | T13: R1013
... A2336: Id2335 | B2336: {=VLOOKUP(A2336,'Customer Names'!$E$2:$H$2336,{2,3,4},0)} -> Mr | C2336: Aaron K | D2336: German | E2336: {=VLOOKUP(A2336,'Medical Examinations'!$J$2:$S$2336,{2,3,4,5,6,7,8,9,10},0)} -> 17.58 | F2336: under weight | G2336: 4.51 | H2336: normal | I2336: No | J2336: No | K2336: No | L2336: 1 | M2336: No | N2336: {=VLOOKUP(A2336,'Hospitalisation Details'!$K$2:$R$2338,{2,3,4,5,6,7,8},0)} -> 33794 | O2336: 30 | P2336: 0 | Q2336: 563.84 | R2336: tier - 2 | S2336: tier - 3 | T2336: R1013

Sheet Final Dashboard

Sheet Pivot 1

Sheet Pivot 2

Sheet Pivot 3

Sheet Pivot 4

Sheet Pivot 5

Sheet Pivot 6
